<robot xmlns:xacro="http://www.ros.org/wiki/xacro">
	<xacro:macro name="wheel" params="suffix *origin parent">
		<joint name="${suffix}_wheel_joint" type="continuous">
			<parent link="${parent}" />
			<child link="${suffix}_wheel_link" />
			<axis xyz="0 0 1" />
			<xacro:insert_block name="origin" />
		</joint>
		<link name="${suffix}_wheel_link">
			<visual>
				<geometry>
					<!-- <cylinder radius="0.05" length="0.05" /> -->
                    <mesh filename="package://diff_bot/description/meshes/Wheel.stl" />
				</geometry>
				<material name="red">
					<color rgba="1.0 0.0 0.0 1.0" />
				</material>
			</visual>
			<collision>
				<geometry>
					<!-- <cylinder radius="0.05" length="0.05" /> -->
                    <mesh filename="package://diff_bot/description/meshes/Wheel.stl" />
				</geometry>
			</collision>
			<inertial>
				<mass value="0.1" />
				<inertia ixx="0.0001" ixy="0.0" ixz="0.0" iyy="0.0001" iyz="0.0" izz="0.0001" />
			</inertial>
		</link>
	</xacro:macro>
</robot>
